Workbook
Name IB12DOSE12Y: #REF!
Name IB12DOSE18Y: #REF!
Name TODAY: #REF!

Sheet Test Plan
A2: Test Script | R2: #VALUE!
A3: CLEO Systems
A4: Project | B4: elevate
A5: Version
A6: Environment | B6: STAGING
B9: Need to record here details regarding the tester, test date and software version for easy reference
B11: Name | C11: Date | D11: Software Version | E11: General Checks | F11: Login and User Profile | G11: VWR Specifics | H11: VWR White Labeling | I11: Audit Log Viewer | J11: Prescribing | K11: CIS2 | L11: ECDS | M11: CPIS | N11: GPC-SD
B12: Status | E12: =IF(OR(COUNTIF(E14:E17, "N/A"),COUNTIF(E14:E17, "X")), 1, 0) -> 1 | F12: =IF(OR(COUNTIF(F14:F17, "N/A"),COUNTIF(F14:F17, "X")), 1, 0) -> 1 | G12: =IF(OR(COUNTIF(G14:G17, "N/A"),COUNTIF(G14:G17, "X")), 1, 0) -> 1 | H12: =IF(OR(COUNTIF(H14:H17, "N/A"),COUNTIF(H14:H17, "X")), 1, 0) -> 1 | I12: =IF(OR(COUNTIF(I14:I17, "N/A"),COUNTIF(I14:I17, "X")), 1, 0) -> 1 | J12: =IF(OR(COUNTIF(J14:J17, "N/A"),COUNTIF(J14:J17, "X")), 1, 0) -> 1 | K12: =IF(OR(COUNTIF(K14:K17, "N/A"),COUNTIF(K14:K17, "X")), 1, 0) -> 1 | L12: =IF(OR(COUNTIF(L14:L17, "N/A"),COUNTIF(L14:L17, "X")), 1, 0) -> 1 | ... P12: =IF(OR(COUNTIF(P14:P17, "N/A"),COUNTIF(P14:P17, "X")), 1, 0) -> 1
B13: Test Completion | E13: =IF(COUNTIF(E14:E17, "=N/A"), "N/A", VLOOKUP(E11, Stats!$B$4:'Stats'!$H$16, 7, FALSE)) -> N/A | F13: =IF(COUNTIF(F14:F17, "=N/A"), "N/A", VLOOKUP(F11, Stats!$B$4:'Stats'!$H$16, 7, FALSE)) -> N/A | G13: =IF(COUNTIF(G14:G17, "=N/A"), "N/A", VLOOKUP(G11, Stats!$B$4:'Stats'!$H$16, 7, FALSE)) -> N/A | H13: =IF(COUNTIF(H14:H17, "=N/A"), "N/A", VLOOKUP(H11, Stats!$B$4:'Stats'!$H$16, 7, FALSE)) -> N/A | I13: =IF(COUNTIF(I14:I17, "=N/A"), "N/A", VLOOKUP(I11, Stats!$B$4:'Stats'!$H$16, 7, FALSE)) -> N/A | J13: =IF(COUNTIF(J14:J17, "=N/A"), "N/A", VLOOKUP(J11, Stats!$B$4:'Stats'!$H$16, 7, FALSE)) -> N/A | K13: =IF(COUNTIF(K14:K17, "=N/A"), "N/A", VLOOKUP(K11, Stats!$B$4:'Stats'!$H$16, 7, FALSE)) -> N/A | L13: =IF(COUNTIF(L14:L17, "=N/A"), "N/A", VLOOKUP(L11, Stats!$B$4:'Stats'!$H$16, 7, FALSE)) -> N/A | ... P13: =IF(COUNTIF(P14:P17, "=N/A"), "N/A", VLOOKUP(P11, Stats!$B$4:'Stats'!$H$16, 7, FALSE)) -> N/A
B14: Jason Ling | E14: N/A | F14: N/A | G14: N/A | H14: N/A | I14: N/A | J14: N/A | K14: N/A | L14: N/A | M14: N/A | N14: N/A | O14: N/A | P14: N/A
B15: Roger Thomas | E15: N/A | F15: N/A | G15: N/A | H15: N/A | I15: N/A | J15: N/A | K15: N/A | L15: N/A | M15: N/A | N15: N/A | O15: N/A | P15: N/A
B16: Stuff Netherton | E16: N/A | F16: N/A | G16: N/A | H16: N/A | I16: N/A | J16: N/A | K16: N/A | L16: N/A | M16: N/A | N16: N/A | O16: N/A | P16: N/A
B17: Olu Oderinde | E17: X | F17: N/A | G17: N/A | H17: N/A | I17: N/A | J17: X | K17: N/A | L17: N/A | M17: N/A | N17: N/A | O17: N/A | P17: N/A

Sheet Stats
A3: Targeted | C3: Tests | D3: Passed | E3: Failed | F3: Cypress | G3: N/A | H3: Completion | I3: Failure Rate
A4: Y | B4: General Checks | C4: =COUNTA(INDIRECT("'"&$B4&"'!D9:D999")) -> 36 | D4: =COUNTIF(INDIRECT("'"&$B4&"'!$E$9:$E$999"), "*PASS*") -> 2 | E4: =COUNTIF(INDIRECT("'"&$B4&"'!$E$9:$E$999"), "*FAIL*") -> 0 | F4: =COUNTIF(INDIRECT("'"&$B4&"'!$E$9:$E$999"), "*CYPRESS*") -> 25 | G4: =COUNTIF(INDIRECT("'"&$B4&"'!$E$9:$E$999"), "*N/A*") -> 9 | H4: =(E4+D4+F4)/(C4-G4) -> 1 | I4: =IF(E4 > 0, E4/(E4+D4), 0) -> 0
A5: N | B5: Login and User Profile | C5: =COUNTA(INDIRECT("'"&$B5&"'!D9:D999")) -> 1 | D5: =COUNTIF(INDIRECT("'"&$B5&"'!$E$9:$E$999"), "*PASS*") -> 0 | E5: =COUNTIF(INDIRECT("'"&$B5&"'!$E$9:$E$999"), "*FAIL*") -> 0 | F5: =COUNTIF(INDIRECT("'"&$B5&"'!$E$9:$E$999"), "*CYPRESS*") -> 0 | G5: =COUNTIF(INDIRECT("'"&$B5&"'!$E$9:$E$999"), "*N/A*") -> 0 | H5: =(E5+D5+F5)/(C5-G5) -> 0 | I5: =IF(E5 > 0, E5/(E5+D5), 0) -> 0
A6: N | B6: VWR Specifics | C6: =COUNTA(INDIRECT("'"&$B6&"'!D9:D999")) -> 26 | D6: =COUNTIF(INDIRECT("'"&$B6&"'!$E$9:$E$999"), "*PASS*") -> 0 | E6: =COUNTIF(INDIRECT("'"&$B6&"'!$E$9:$E$999"), "*FAIL*") -> 0 | F6: =COUNTIF(INDIRECT("'"&$B6&"'!$E$9:$E$999"), "*CYPRESS*") -> 0 | G6: =COUNTIF(INDIRECT("'"&$B6&"'!$E$9:$E$999"), "*N/A*") -> 0 | H6: =(E6+D6+F6)/(C6-G6) -> 0 | I6: =IF(E6 > 0, E6/(E6+D6), 0) -> 0
A7: N | B7: VWR White Labeling | C7: =COUNTA(INDIRECT("'"&$B7&"'!D9:D999")) -> 50 | D7: =COUNTIF(INDIRECT("'"&$B7&"'!$E$9:$E$999"), "*PASS*") -> 0 | E7: =COUNTIF(INDIRECT("'"&$B7&"'!$E$9:$E$999"), "*FAIL*") -> 0 | F7: =COUNTIF(INDIRECT("'"&$B7&"'!$E$9:$E$999"), "*CYPRESS*") -> 0 | G7: =COUNTIF(INDIRECT("'"&$B7&"'!$E$9:$E$999"), "*N/A*") -> 0 | H7: =(E7+D7+F7)/(C7-G7) -> 0 | I7: =IF(E7 > 0, E7/(E7+D7), 0) -> 0
A8: N | B8: Audit Log Viewer | C8: =COUNTA(INDIRECT("'"&$B8&"'!D9:D999")) -> 6 | D8: =COUNTIF(INDIRECT("'"&$B8&"'!$E$9:$E$999"), "*PASS*") -> 0 | E8: =COUNTIF(INDIRECT("'"&$B8&"'!$E$9:$E$999"), "*FAIL*") -> 0 | F8: =COUNTIF(INDIRECT("'"&$B8&"'!$E$9:$E$999"), "*CYPRESS*") -> 0 | G8: =COUNTIF(INDIRECT("'"&$B8&"'!$E$9:$E$999"), "*N/A*") -> 0 | H8: =(E8+D8+F8)/(C8-G8) -> 0 | I8: =IF(E8 > 0, E8/(E8+D8), 0) -> 0
A9: Y | B9: Prescribing | C9: =COUNTA(INDIRECT("'"&$B9&"'!D9:D999")) -> 76 | D9: =COUNTIF(INDIRECT("'"&$B9&"'!$E$9:$E$999"), "*PASS*") -> 20 | E9: =COUNTIF(INDIRECT("'"&$B9&"'!$E$9:$E$999"), "*FAIL*") -> 0 | F9: =COUNTIF(INDIRECT("'"&$B9&"'!$E$9:$E$999"), "*CYPRESS*") -> 0 | G9: =COUNTIF(INDIRECT("'"&$B9&"'!$E$9:$E$999"), "*N/A*") -> 56 | H9: =(E9+D9+F9)/(C9-G9) -> 1 | I9: =IF(E9 > 0, E9/(E9+D9), 0) -> 0
A10: N | B10: CIS2 | C10: =COUNTA(INDIRECT("'"&$B10&"'!D9:D999")) -> 17 | D10: =COUNTIF(INDIRECT("'"&$B10&"'!$E$9:$E$999"), "*PASS*") -> 0 | E10: =COUNTIF(INDIRECT("'"&$B10&"'!$E$9:$E$999"), "*FAIL*") -> 0 | F10: =COUNTIF(INDIRECT("'"&$B10&"'!$E$9:$E$999"), "*CYPRESS*") -> 0 | G10: =COUNTIF(INDIRECT("'"&$B10&"'!$E$9:$E$999"), "*N/A*") -> 0 | H10: =(E10+D10+F10)/(C10-G10) -> 0 | I10: =IF(E10 > 0, E10/(E10+D10), 0) -> 0
A11: N | B11: ECDS | C11: =COUNTA(INDIRECT("'"&$B11&"'!D9:D999")) -> 17 | D11: =COUNTIF(INDIRECT("'"&$B11&"'!$E$9:$E$999"), "*PASS*") -> 0 | E11: =COUNTIF(INDIRECT("'"&$B11&"'!$E$9:$E$999"), "*FAIL*") -> 0 | F11: =COUNTIF(INDIRECT("'"&$B11&"'!$E$9:$E$999"), "*CYPRESS*") -> 0 | G11: =COUNTIF(INDIRECT("'"&$B11&"'!$E$9:$E$999"), "*N/A*") -> 0 | H11: =(E11+D11+F11)/(C11-G11) -> 0 | I11: =IF(E11 > 0, E11/(E11+D11), 0) -> 0
A12: N | B12: CPIS | C12: =COUNTA(INDIRECT("'"&$B12&"'!D9:D999")) -> 28 | D12: =COUNTIF(INDIRECT("'"&$B12&"'!$E$9:$E$999"), "*PASS*") -> 0 | E12: =COUNTIF(INDIRECT("'"&$B12&"'!$E$9:$E$999"), "*FAIL*") -> 0 | F12: =COUNTIF(INDIRECT("'"&$B12&"'!$E$9:$E$999"), "*CYPRESS*") -> 0 | G12: =COUNTIF(INDIRECT("'"&$B12&"'!$E$9:$E$999"), "*N/A*") -> 0 | H12: =(E12+D12+F12)/(C12-G12) -> 0 | I12: =IF(E12 > 0, E12/(E12+D12), 0) -> 0
A13: N | B13: GPC-SD | C13: =COUNTA(INDIRECT("'"&$B13&"'!D18:D999")) -> 21 | D13: =COUNTIF(INDIRECT("'"&$B13&"'!$E$9:$E$999"), "*PASS*") -> 1 | E13: =COUNTIF(INDIRECT("'"&$B13&"'!$E$9:$E$999"), "*FAIL*") -> 1 | F13: =COUNTIF(INDIRECT("'"&$B13&"'!$E$9:$E$999"), "*CYPRESS*") -> 0 | G13: =COUNTIF(INDIRECT("'"&$B13&"'!$E$9:$E$999"), "*N/A*") -> 0 | H13: =(E13+D13+F13)/(C13-G13) -> 0.095238095 | I13: =IF(E13 > 0, E13/(E13+D13), 0) -> 0.5
A14: N | B14: BaRS | C14: {=COUNTA(INDIRECT("'"&$B14&"'!D9:D999"))} -> 60 | D14: {=COUNTIF(INDIRECT("'"&$B14&"'!$E$9:$E$999"), "*PASS*")} -> 0 | E14: {=COUNTIF(INDIRECT("'"&$B14&"'!$E$9:$E$999"), "*FAIL*")} -> 0 | F14: {=COUNTIF(INDIRECT("'"&$B14&"'!$E$9:$E$999"), "*CYPRESS*")} -> 0 | G14: {=COUNTIF(INDIRECT("'"&$B14&"'!$E$9:$E$999"), "*N/A*")} -> 0 | H14: =(E14+D14+F14)/(C14-G14) -> 0 | I14: =IF(E14 > 0, E14/(E14+D14), 0) -> 0
B17: TOTALS | C17: =SUM(IF($A3="Y",$C3,0),IF($A4="Y",$C4,0),IF($A5="Y",$C5,0),IF($A6="Y",$C6,0),IF($A7="Y",$C7,0),IF($A8="Y",$C8,0),IF($A9="Y",$C9,0),IF($A10="Y",$C10,0),IF($A12="Y",$C12,0),IF($A13="Y",$C13,0),IF($A14="Y",$C14,0),IF($A15="Y",$C15,0),IF($A16="Y",$C16,0)) -> 112 | D17: =SUM(IF($A3="Y",$D3,0),IF($A4="Y",$D4,0),IF($A5="Y",$D5,0),IF($A6="Y",$D6,0),IF($A7="Y",$D7,0),IF($A8="Y",$D8,0),IF($A9="Y",$D9,0),IF($A10="Y",$D10,0),IF($A12="Y",$D12,0),IF($A13="Y",$D13,0),IF($A14="Y",$D14,0),IF($A15="Y",$D15,0),IF($A16="Y",$D16,0)) -> 22 | E17: =SUM(IF($A3="Y",$E3,0),IF($A4="Y",$E4,0),IF($A5="Y",$E5,0),IF($A6="Y",$E6,0),IF($A7="Y",$E7,0),IF($A8="Y",$E8,0),IF($A9="Y",$E9,0),IF($A10="Y",$E10,0),IF($A12="Y",$E12,0),IF($A13="Y",$E13,0),IF($A14="Y",$E14,0),IF($A15="Y",$E15,0),IF($A16="Y",$E16,0)) -> 0 | F17: =SUM(IF($A4="Y",$F4,0),IF($A5="Y",$F5,0),IF($A6="Y",$F6,0),IF($A7="Y",$F7,0),IF($A8="Y",$F8,0),IF($A9="Y",$F9,0),IF($A10="Y",$F10,0),IF($A12="Y",$F12,0),IF($A13="Y",$F13,0),IF($A14="Y",$F14,0),IF($A15="Y",$F15,0),IF($A16="Y",$F16,0)) -> 25 | G17: =SUM(IF($A3="Y",$G3,0),IF($A4="Y",$G4,0),IF($A5="Y",$G5,0),IF($A6="Y",$G6,0),IF($A7="Y",$G7,0),IF($A8="Y",$G8,0),IF($A9="Y",$G9,0),IF($A10="Y",$G10,0),IF($A12="Y",$G12,0),IF($A13="Y",$G13,0),IF($A14="Y",$G14,0),IF($A15="Y",$G15,0),IF($A16="Y",$G16,0)) -> 65 | H17: =(E17+D17+F17)/(C17-G17) -> 1 | I17: =IF(E17 > 0, E17/(E17+D17), 0) -> 0
O1046: #REF!
O1047: #REF!
O1048: #REF!
O1049: #REF!
O1050: #REF!
O1051: #REF!
O1052: #REF!
O1053: #REF!
O1054: #REF!
O1055: #REF!

Sheet General Checks
A2: Product | B2: elevate | D2: #VALUE!
A3: Version
A4: Environment | B4: STAGING
A5: Testing Scenario
A8: Domain | B8: GIven | C8: When | D8: Then | E8: Result (pass or fail) | F8: Actual Result (if different) | G8: Jira Ticket
A9: User Signup | B9: Given I am logged in as a super admin | C9: When I select service provider > users> add new user | D9: Then I am able to invite a new user | E9: pass | F9: Invite sent, however when user clicked on the link sent to email and inputted password then login with new password, the screen presented to user says Pending Invitation - The instruction on that screen should be clear to user to click the pending invitation button to continue with the onboarding
B10: Given that new user has received an invitation email | C10: When they click on the link | D10: Then they are able to set their password and are taken to the profile page | E10: Cypress
D11: And when they have completed their profile they can access the site they have been invited to. | E11: Cypress
A12: Landing page | B12: Given the user is on the login page | C12: When they enter a valid user name and password and click login | D12: Then they are successfully logged in and taken to the dashboard page | E12: Cypress
D13: And the page shows encounters in progress and cases | E13: Cypress
A14: Patient Registration | B14: Given I want to register a patient | C14: When I enter a valid NHS number | D14: Then the patient is found and registered correctly | E14: Cypress
B15: Given I want to register a patient | C15: When I use demogrpahics to search PDS | D15: Then the patient is found and registered correctly | E15: Cypress
A16: Patient load | B16: Given I want to search for a patient | C16: When I type part of the patients name / postcode | D16: Then a list of results are displayed including the patient you are searching for | E16: Cypress
C17: And When I select a patient | D17: Then it is loaded and their details are displayed in the banner correctly | E17: Cypress
A18: Add encounter | B18: Given I am viewing a patients timeline | C18: When I click add and select a form | D18: Then the form is loaded and I am able to add information and save | E18: Cypress
A19: PDF generation | B19: Given I have added a consultation note to a patient | C19: When I click on generate PDF and continue | D19: Then a PDF is generated with the correct information and is displayed in a size that can be easily read. | E19: Cypress
A20: Add case | B20: Given I have loaded a patient and selected the cases tab | C20: When I click add and select a case type | D20: Then the case is loaded and I am able to add information and save | E20: Cypress
D21: And I can link an encounter to the case (either a new or an exisitng one) | E21: Cypress
A22: Add prescription | B22: Given I have loaded a patient and selected the Meds tab | C22: When I click add prescription | D22: Then I can go through all the steps and add a prescription | E22: pass
A23: Meds | B23: Given a prescription is issued for a patient | C23: When I click on 'Copy Prescription Id' | D23: Then the user is notified with the text "Copied!" | E23: Cypress
A24: Audit Log | B24: Given I have carried out a number of actions on a patients record | C24: When I view the audit log | D24: Then there are entries for those actions in the log | E24: Cypress
A25: About Tab | B25: Given I have loaded a patient and selected the About tab | C25: When I view the details | D25: Then all the patient information is displayed correctly | E25: Cypress
A26: Patient Banner | B26: Given I have registered a patient who is < 2 days old | C26: When I view the patient banner | D26: Then their age is displayed in hours | E26: Cypress
B27: Given I have registered a patient who is > 2 days but < 4 weeks old | C27: When I view the patient banner | D27: Then their age is displayed in days | E27: Cypress
B28: Given I have registered a patient who is > 4 weeks but <1 year old | C28: When I view the patient banner | D28: Then their age is displayed in weeks and days | E28: Cypress
B29: Given I have registered a patient who is >1 year but <2 years old | C29: When I view the patient banner | D29: Then their age is displayed in months and days | E29: Cypress
B30: Given I have registered a patient who is >2 year but <18 years old | C30: When I view the patient banner | D30: Then their age is displayed in years and months | E30: Cypress
B31: Given I have registered a patient who is >18 years old | C31: When I view the patient banner | D31: Then their age is displayed in years | E31: Cypress
A32: In Progress | B32: Given I have logged in to elevate | C32: When I click on In Progress | D32: Then the in progress page is displayed and I can see any encounters and prescriptions that are in progress | E32: Cypress
A33: Cases | B33: Given I have logged in to elevate | C33: When I click on Cases | D33: Then I am taken to the cases page and a list of all open cases is displayed | E33: Cypress
A34: Reports | B34: Given I have logged in to elevate | C34: When I click on reports | D34: Then I am taken to the reports page and the reports tabs are available | E34: Cypress
C35: And if I click on one of the tabs and select a report to download | D35: Then the report is downloaded and the data within it is correct | E35: Cypress
A36: Ummanu360 specific checks | B36: Given I have logged in to elevate to the Ummanu360 site as a Ummanu360 user (test01@badger.co.uk) | C36: When the landing page is loaded | D36: Then the only sidebar options are dashboard, cases, service provider and help | E36: N/A
D37: And the Launch Telemedicine button is present | E37: N/A
A38: Finalise or Finalise & close | B38: Given I have logged into the Ummanu360 or Assurance360 site | C38: When I have started a consultation in Ummanu which has opened the case and encounter in Elevate | D38: Then the finalise & close case button should be present but not the finalise button | E38: N/A
B39: Given I have logged into the Ummanu360 or Assurance360 site | C39: When I load a patient in elevate and add a consulation note | D39: Then the finalise & close case button should NOT be present but the finalise button shoud be present | E39: N/A
B40: Given I have logged into an org other than the Ummanu360 or Assurance360 site | C40: When I load a patient in elevate and add a consulation note | D40: Then the finalise & close case button should NOT be present but the finalise button shoud be present | E40: N/A | F40: part of CIS2 tests
A41: CIS2 (requires smartcard) | B41: Given a user has logged in with username and password | C41: When the user inserts their smartcard | D41: Then they are able to authenticate the card and associate it with their elevate account | E41: N/A | F41: part of CIS2 tests
B42: Given the user has linked their smartcard to their elevate account | C42: When they click Log in with My Care Identity | D42: Then they the role selection page is displayed with the correct organisation and the user can select one and is taken to the dashboard page | E42: N/A | F42: part of CIS2 tests
A43: CPIS (requires smartcard) | B43: Given the user has logged in without their smartcard and is therefore NOT authorised to access CPIS information | C43: When they load an eligible patient who has CPIS information | D43: Then the CPIS information will not be returned and a message will be displayed stating the user does not have permission to view | E43: N/A | F43: part of CIS2 tests
...

Sheet Login and User Profile
A2: Product | B2: elevate | D2: #VALUE!
A3: Version
A4: Environment | B4: STAGING
A5: Testing Scenario | B5: User login and authentication
A8: Domain | B8: GIven | C8: When | D8: Then | E8: Result (pass or fail) | F8: Actual Result (if different) | G8: Jira Ticket
A9: Logout | B9: GIVEN that my Elevate session has timed out due to a period of 60 minutes of inactivity, and a toast message appears stating that "You have been automatically logged out" | C9: WHEN I log back in to Elevate using my login credentials | D9: THEN the toast message shall dissappear | F9: toast message does not dissapear

Sheet VWR Specifics
A2: Product | B2: elevate | D2: #VALUE!
A3: Version
A4: Environment | B4: STAGING
A5: Testing Scenario | B5: VWR Specifics
A8: Domain | B8: GIven | C8: When | D8: Then | E8: Result (pass or fail) | F8: Actual Result (if different) | G8: Jira Ticket
B9: Given the user is logged in to elevate in an org that is setup for VWR (either VWR or Assurance) | C9: When they click Launch Telemedicine | D9: Then the VWR telemedicine application opens in a new tab
B10: Given the user has logged into the Telemedicine application | C10: When a user is successfully logged in | D10: Then the Consultations view is displayed
B11: Given the user wishes to consult the next patient | C11: When they click next patient in VWR | D11: Then the correct patient is loaded in elevate
D12: And a new case is present for that patient with a new encounter
B13: Given the user wishes to add a prescription to the case | C13: When they click the Save as Draft button | D13: Then the encounter is saved and refreshed
C14: When they click +Prescription | D14: Then the prescription form opens in the encounter window
D15: And they can search for a medication
D16: And they can select a medication, complete the form and add to basket
D17: And they can proceed to issue an EPS prescription (PDS verified patients only) | F17: will be covered by CIS2 testing
D18: And they can proceed to issue a paper prescription (non PDS verified patients) | F18: resizing the windows causes the pharmacy details to be displayed incorrectly | G18: FEM-36187
D19: And they are returned to the encounter / case when the prescription is completed | F19: screen remains on the print prescription form, have to click close to be returned to the encounter/case
B20: Given the user wishes to enter a coding for the encounter | C20: When they click on the coding field | D20: Then the approved list of options is displayed
D21: And they can select one and one only from the list
B22: Given the user wishes to enter a coding for the encounter | C22: When they click on the coding field | D22: Then they can type in the field to search
D23: And they can select one and one only from the returned search
B24: Given the user wishes to record an urgency | C24: When they click on the urgency field | D24: Then the three options are displayed as Routine, Urgent and Emergency
D25: And they can select one and one only
B26: Given the user wishes to record an outcome | C26: When they click on the outcome field | D26: Then the approved list of options is displayed
D27: And they can select one or more from the list
B28: Given the user wishes to record an outcome | C28: When they click on the outcome field | D28: Then they can type in the field to search
D29: And they can select one or more from the returned search list
B30: Given the user has completed the encounter with the patient and entered a coding, urgency and outcome | C30: When they click Finalise & Close Case | D30: Then the encounter and the case will be saved
D31: And the case status will be set to resolved | F31: Change to "And the case status will be set to closed"
D32: And the encounter will be set to Finalised
D33: And the consultation is closed in VWR
B34: Given the user wishes to consult the next patient | C34: When they click next patient in VWR | D34: Then the correct patient is loaded and the previous patients information is no longer present

Sheet VWR White Labeling
A2: Product | B2: elevate | D2: #VALUE!
A3: Version
A4: Environment | B4: STAGING
A5: Testing Scenario | B5: VWR White Labeling
A8: Domain | B8: GIven | C8: When | D8: Then | E8: Result (pass or fail) | F8: Actual Result (if different) | G8: Jira Ticket
A9: Login | B9: Given a user wishes to log in | C9: When they visit the login page | D9: Then the page is displayed in the Ummanu colours and with their logo
C10: When the user enters a valid usrname and password and clicks Login | D10: Then the site selection page is displayed and then can select a site and login
D11: And the dasboard page is displayed correctly in the Ummanu colours
A12: Dashboard Page | B12: Given the user has logged in | C12: When they view the dashboard page | D12: Then the page is displayed in the Ummanu colours and with their logo
D13: side bar
D14: banner
D15: Entries in progress
D16: My Open cases
B17: Given the user wishes to search for a patient | C17: When they type in a search criteria | D17: Then a list of matching patients is returned
D18: And they can select and load a patient
A19: Patients | B19: Given the user clicks Patients in the side nav | C19: When the page loads | D19: Then it is displayed correctly in the Ummanu colours
C20: And when the user uses the patient searchbar | D20: Then they can successfully search for and load a patient
D21: And the patient banner is displayed correctly
D22: And the tabs have the correct Ummanu colours
A23: Timeline - Encounters | B23: Given the user wishes to add an encounter for a patient | C23: When they click Add | D23: Then they are able to add an encounter form
C24: And when they enter some details in the form and save as draft | D24: Then the form is saved as draft
C25: And when they add or change information in the form and finalise | D25: Then the form is finalised
D26: And all the information is correct including the last modified info
B27: Given the user wishes to download a PDF of the encounter | C27: When they click the PDF button | D27: Then the PDF is downloaded without error
A28: Patient Meds Tab | B28: Given the user wishes to prescribe a drug | C28: When they click on the meds tab | D28: Then the prescribing form is displayed correctly in the Ummanu colours
C29: And when they click prescription | D29: Then they can search for a drug
C30: And when they select a drug | D30: Then it can be added to the basket
D31: Then the user can complete the prescription
A32: Patient Cases Tab | B32: Given the user wishes to view the cases for a patient | C32: When they load a patient and click on the cases tab | D32: Then the patients case(s) is displayed correctly in the Ummanu colours
D33: And the user can expand and collapse any linked encounters
D34: And the user can close (collapse) the case
D35: And the user can add a new case
A36: Patient About Tab | B36: Given the user wishes to view demographic information for a loaded patient | C36: When the user clicks on the about tab | D36: Then the page is displayed correcty in the Ummanu colours
D37: And the PDS section is not editable
D38: And an email and phone number can be added to the Additional informtion section
D39: And the registration status of the patient can be changed
A40: In Progress - Sidebar | B40: Given the user wishes to view In progress items | C40: When they click In Progress on the sidebar | D40: Then the page is displayed correcty in the Ummanu colours
D41: And the correct In progress encounters are displayed
D42: And the user can access the filters and filter the list
C43: And when the user clicks on an encounter | D43: Then they are taken to the patient and the encounter is displayed
...

Sheet Audit Log Viewer
A2: Product | B2: elevate | D2: #VALUE!
A3: Version
A4: Environment | B4: STAGING
A5: Testing Scenario | B5: Audit Log Viewer
A8: Domain | B8: GIven | C8: When | D8: Then | E8: Result (pass or fail) | F8: Actual Result (if different) | G8: Jira Ticket
A9: Prescribing | B9: GIVEN that I have created prepared the contents of an EPS prescription | C9: When I view the audit trail | D9: THEN it shall be be possible to see:- - The time of the transaction - Who performed the transaction - The patient involved in the transaction - The resultant payload of the transaction
B10: GIVEN that I have submitted an EPS prescription to the signing service | C10: When I view the audit trail | D10: THEN it shall be be possible to see:- - The time of the transaction - Who performed the transaction - The patient involved in the transaction - The resultant payload of the transaction
B11: GIVEN that I have sent the contents of an EPS prescription | C11: When I view the audit trail | D11: THEN it shall be be possible to see:- - The time of the transaction - Who performed the transaction - The patient involved in the transaction - The resultant payload of the transaction
A12: Encounters | B12: Given that I have added an encounter for a patient | C12: When I view the audit log | D12: Then there is an entry in the log
A13: Cases | B13: Given that I have added a case for a patient | C13: When I view the audit log | D13: Then there is an entry in the log
A14: Audit of access | B14: Given that a user has viewed the audit log | C14: When the audit log is viewed again | D14: Then there is an entry in the log for QUERY_AUDIT_LOG_SUCCESS

Sheet Prescribing
A2: Product | B2: elevate | D2: #VALUE!
A3: Version
A4: Environment | B4: STAGING
A5: Testing Scenario | B5: Audit Log Viewer
A8: Domain | B8: GIven | C8: When | D8: Then | E8: Result (pass or fail) | F8: Actual Result (if different) | G8: Jira Ticket
A9: Prescription Layout | B9: GIVEN that I have generated a FP10 prescription for an CC medication (e.g. Co-cyprindiol 2000microgram/35microgram tablets) | C9: When I view the printed FP10 | D9: THEN the item shall be endorsed as CC | E9: pass
B10: GIVEN that I have generated a FP10 prescription for an AF medication (e.g. Fortisip 2kcal liquid) | C10: When I view the printed FP10 | D10: THEN the item shall be endorsed as AF (it will also be endorsed as ACBS also) | E10: pass | F10: endorsment of AF not visible anywhere note: The endorsement of AF and ACBS is now visible
B11: GIVEN that I have generated a FP10 prescription for a Controlled medication (e.g. Tramadol 100mg/ml oral drops) with a total quantity of 97.25ml | C11: When I view the printed FP10 | D11: THEN the item shall be endorsed as CD and the amount should be in words (e.g. 97.25 (NINETY SEVEN POINT TWO FIVE) ML ) | E11: pass
B12: GIVEN that I have generated a FP10 prescription for an SLS medication (e.g. Clobazam 10mg tablets) | C12: When I view the printed FP10 | D12: THEN the item shall be endorsed as SLS and CD | E12: pass
B13: GIVEN that I have generated a FP10 prescription for an ACBS medication (e.g. Carob seed flour powder) | C13: When I view the printed FP10 | D13: THEN the item shall be endorsed as ACBS | E13: pass
A14: Patient Details | B14: GIVEN that I have generated a FP10 prescription for a patient | C14: When I view the printed FP10 | D14: THEN the patient’s name will appear in the format “Mr James Smith” | E14: pass
B15: GIVEN that I have generated a FP10 prescription for a patient | C15: When I view the printed FP10 | D15: THEN the patient’s DoB will appear in the format “DD/MM/YYYY” | E15: pass
B16: GIVEN that I have generated a FP10 prescription for a patient | C16: When I view the printed FP10 | D16: THEN the patient’s address will appear: with at least one space below the patient’s name in a multiline format not exceeding FOUR lines with the postcode being included on the RHS of the LAST line | E16: pass
B17: GIVEN that I have generated a FP10 prescription for a patient | C17: When I view the printed FP10 | D17: THEN the patient’s NHS number will appear right-justified in the format “XXXXXXXXXX” with at least one space below the last line of the address | E17: pass | G17: https://cleosystems.atlassian.net/browse/UE-462
B18: GIVEN that I have generated a prescription for a patient with a long name | C18: When I view the name | D18: THEN the surname and forename shall be presented on separate lines, but it shall not “wrap” or split on partial words. | E18: pass
A19: Endorsements | B19: GIVEN that the user is a “Clinical Practitioner” | C19: When I view the printed FP10 and look for endorsements | D19: THEN the script will NOT be endorsed | E19: pass
B20: GIVEN that the user is a “Local Clinical Practitioner” | C20: When I view the printed FP10 and look for endorsements | D20: THEN the script will NOT be endorsed | E20: pass
B21: GIVEN that the user is a “Nurse” with a prescriber type of “Nurse Prescriber” | C21: When I view the printed FP10 and look for endorsements | D21: THEN the script will be endorsed “COMMUNITY PRACTITIONER NURSE PRESCRIBER” and “PN” in the relevant organisations | E21: pass | G21: https://cleosystems.atlassian.net/browse/UE-461
B22: GIVEN that the user is a “Nurse” with a prescriber type of “Independent Prescriber” | C22: When I view the printed FP10 and look for endorsements | D22: THEN the script will be endorsed “NURSE INDEPENDENT/SUPPLEMENTARY PRESCRIBER” and “PN” in the relevant organisations | E22: pass
B23: GIVEN that the user is a “Nurse” with a prescriber type of “Supplementary Prescriber” | C23: When I view the printed FP10 and look for endorsements | D23: THEN the script will be endorsed “NURSE INDEPENDENT/SUPPLEMENTARY PRESCRIBER” and “PN” in the relevant organisations | E23: pass
A24: Prescriber Details | B24: GIVEN that I have generated an FP10 prescription | C24: When I view the prescriber’s name | D24: THEN the prescriber’s name shall be presented in the format of TITLE INITIAL SURNAME and formatted accordingly | E24: pass
B25: GIVEN that I have generated an FP10 prescription | C25: When I view the prescriber’s PIN/DIN/NMC code | D25: THEN the prescriber’s PIN / DIN / NMC shall be presented to the right of their name | E25: pass
B26: GIVEN that I have generated an FP10 prescription | C26: When I view the organisation’s cost centre / address | D26: THEN the address shall span no more than three lines, and shall not “wrap” or be split on partial words | E26: pass
B27: GIVEN that I have generated an FP10 prescription | C27: When I view the organisation’s telephone number | D27: THEN the organisation’s telephone number shall be presented immediately below the address | E27: pass
B28: GIVEN that I have generated an FP10 prescription | C28: When I view the organisation’s CCG name | D28: THEN the organisation’s CCG name shall be presented immediately below the telephone number | E28: pass
A29: EPS - Repudiation Statement | B29: GIVEN that I have a PDS synchronised patient and I have selected EPS as a prescribing route | C29: When I select "Issue with EPS" | D29: THEN the non-repudiation statement will be shown. The statement shall contain the wording "The system will sign the content displayed here on your behalf., by means of information stored on your Smart Card as an Advanced Electronic Signature. By entering your passcode you affirm your intention to digitally sign and issue this ETP. Do you want to proceed?" | E29: n/a
B30: GIVEN I have a SmartCard inserted, and I enter an invalid PIN at the non-repudiation statement | C30: When I click "Proceed" | D30: THEN the system shall warn me that the PIN number entered is not correct. | E30: n/a
B31: GIVEN I have a SmartCard inserted, and I enter an invalid PIN at the non-repudiation statement | C31: When I have been informed that this is incorrect | D31: THEN the system shall offer me the ability to re-enter the PIN, or cancel the signing process | E31: n/a
B32: GIVEN I have a SmartCard inserted, and I enter an invalid PIN at the non-repudiation statement | C32: When I wish to cancel the signing process because I've forgotten my PIN number | D32: THEN I shall have the option to "Go back" to the Prescribing screen (Stage 1 Prepare) | E32: n/a
B33: GIVEN I have a SmartCard inserted, and I enter an invalid PIN at the non-repudiation statement | C33: When I enter an invalid PIN for "n" number of times (where "n" is the number of attempt allowed to enter a PIN) | D33: THEN the system shall offer me the ability to re-enter the PIN, or cancel the signing process | E33: n/a
B34: GIVEN I have a SmartCard inserted, and I enter an invalid PIN at the non-repudiation statement | C34: When I enter an invalid PIN for "n+1" number of times (where "n" is the number of attempts allowed to enter a PIN) | D34: THEN the system shall inform me that I've exceeded the maximum number of authentication attempts and | E34: n/a
B35: GIVEN I have not got a SmartCard inserted | C35: When I click "Proceed" | D35: THEN the system shall warn me that the SmartCard is not present | E35: n/a | G35: If a card has been withdrawn, then the session closes regardless, so it is impossible to get into this position
B36: GIVEN I have got a SmartCard inserted and I've entered the correct PIN number | C36: When I click on "Proceed" | D36: THEN the system shall confirm that the PIN is correct and return me to the Elevate UI, indicating that the process has been successful. | E36: n/a
A37: EPS - Error Conditions | B37: GIVEN I am attempting to send an EPS message with invalid message content | C37: When I perform the sending operation | D37: THEN I shall be synchronously informed that the send has failed, and allowed to return to the Prescribing screen. | E37: n/a
B38: GIVEN I am attempting to send an EPS message with invalid message signature | C38: When I perform the sending operation | D38: THEN I shall be synchronously informed that the send has failed, and allowed to return to the Prescribing screen. | E38: n/a
B39: GIVEN I am attempting to send an EPS message and Spine is unresponsive | C39: When I perform the sending operation | D39: THEN the system shall time-out graciously, inform me of the timeout and allow me to return to the Prescribing screen. | E39: n/a
A40: EPS - More than FOUR items | B40: GIVEN that I have added FOUR medication items to a prescription | C40: When I generate the EPS prescription | D40: THEN the system shall generate ONE prescription, with ONE prescription UUID that will be traceable through the EPS Tracker | E40: n/a
B41: GIVEN that I have added FIVE medication items to a prescription | C41: When I generate the EPS prescription | D41: THEN the system shall generate TWO prescriptions, with TWO prescription UUIDS that will be traceable through the EPS Tracker | E41: n/a
B42: GIVEN that I have added NINE medication items to a prescription | C42: When I generate the EPS prescription | D42: THEN the system shall generate THREE prescriptions, with THREE prescription UUIDS that will be traceable through the EPS Tracker | E42: n/a
A43: EPS - Link to Tracker | B43: GIVEN that I am viewing the detail of an EPS prescription that has been sent to Spine | C43: When I click on the link to the EPS tracker | D43: THEN the EPS tracker shall open in a new tab, with details of the prescription presented (subject to the behaviour of the EPS Tracking Portal) | E43: n/a
...

Sheet CIS2
A2: Product | B2: elevate | D2: #VALUE!
A3: Version
A4: Environment | B4: STAGING
A5: Testing Scenario | B5: CIS2
A8: Domain | B8: GIven | C8: When | D8: Then | E8: Result (pass or fail) | F8: Actual Result (if different) | G8: Jira Ticket
A9: Login with Elevate 2FA Username / Password | B9: GIVEN the user already has an Elevate account and a NHS SmartCard | C9: WHEN the user logs in with Elevate using their username and password | D9: THEN the user is able to select any active organisation/role from the selection list
A10: Link an Elevate Organisation/Role | B10: GIVEN that the user wishes to associate their local Elevate account with CIS2 | C10: WHEN they log in to Elevate, and select "Profile" --> "Care Identity Service" | D10: THEN they are presented with the ability to associate their local account with CIS2
A11: Linked Organisation/Role Account | B11: GIVEN the user already has an organisation/role linked to their CIS2 and wishes to login using their SmartCard | C11: WHEN the user inserts their SmartCard into the card reader without any applications running | D11: THEN they are presented with the NHS Identity Agent requesting their passcode
B12: GIVEN the user is presented with the NHS Identity Agent and their SamrtCard is inserted | C12: WHEN the user enters the correct passcode | D12: THEN they are given a choice of organisation/roles associated with their NHS account
B13: GIVEN the user is presented with the NHS Identity Agent and their SmartCard is inserted | C13: WHEN the user selects an organisation/role and clicks the OK button | D13: THEN the Elevate solution's dashboard page is displayed on the screen for the correct organisation/role they have just selected
A14: Link Authorised Organisation | B14: GIVEN the user has inserted their SmartCard and successfully authenticated themselves using their passcode | C14: WHEN the user selects organisation / role "profile" from the Identity Agent UI user has an active account at that organisation | D14: THEN the user is logged straight into Elevate at that organisation without further user input
A15: No active link to organisation | B15: GIVEN the user has inserted their SmartCard and sucessfully authenticated themselves using their passcode | C15: WHEN the user selects organisation / role "profile" from the NHS Identity Agent UI user DOES NOT HAVE an active account at that organisation | D15: THEN the user is warned that they do not have an active account and that they should contact their local admninistrator | G15: https://evahealthtech.atlassian.net/jira/software/c/projects/EJ/boards/80?modal=detail&selectedIssue=EJ-1272
A16: Single Linked Organisation with Multiple Roles | B16: GIVEN the user has multiple Elevate roles at a single organisation (ie. ORG-A - Nurse, ORG-A - Clerical, ORG-A - Clinical Practitioner) | C16: WHEN the user autheticates themselves using their SmartCard / passcode using the NHS Identity Agent is automatically logged into Elevate at that organisation | D16: THEN the Elevate organisation/role selection list is displayed showing all active roles for the current user at that organisation ONLY
A17: Link Inactive Role | B17: GIVEN that a new user is set up at ORG-A | C17: WHEN the user logs in using their username / password and configures their profile clicks on the CIS2 button inserts their SmartCard selects an Organisation that they don't have an active role at (i.e. NOT ORG-A) | D17: THEN the user will be advised that they do not have a role at that organisation | G17: https://evahealthtech.atlassian.net/jira/software/c/projects/EJ/boards/80?modal=detail&selectedIssue=EJ-1274
A18: Remove Linked Organisation | B18: GIVEN that a user wishes to disconnect their CIS2 account from their Elevate account | C18: WHEN the user navigates to "Profile" -> "Care Identity" and selects "Disconnect" | D18: THEN I shall be notified that my account has been disconnected AND I am logged out from the Elevate solution AND I shall be able to reconnect my account if necessary
A19: Switch to Another Organisation/Role | B19: GIVEN the user is an authorised Elevate user with a NHS SmartCard registered for 2 different organisations | C19: WHEN the user inserts their CIC and selects ORG-A from the NHS site selector the user attempts to switch role | D19: THEN the user MAY switch roles within the organisation ORG-A selected during the NHS Identity Agent login process
B20: GIVEN the user is an authorised Elevate user with a NHS SmartCard registered for 2 different organisations | C20: WHEN the user inserts their CIC and selects ORG-A from the NHS site selector the user attempts to switch organisation | D20: THEN the user MAY NOT switch organisations to ORG-B | G20: https://evahealthtech.atlassian.net/browse/EJ-1664
A21: Remove Card for Different organisation/role | B21: GIVEN the user is an authorised Elevate user with a NHS CIC linked to more than ONE orgranisation | C21: WHEN the user wishes to change organisations they remove their CIC | D21: THEN the user is logged out from Elevate
B22: GIVEN the user is an authorised Elevate user with a NHS CIC linked to more than ONE orgranisation | C22: WHEN the user reinserts their CIC enters the correct passcode | D22: THEN the user is able to select a linked organisation/role from the NHS selection list and are logged into that organisation AND the CIS2 agent shows the correct organisation
A23: Available Roles | B23: GIVEN that I have authenticated myself using CIS2 to an organisation registered on my SmartCard | C23: When I select my desired role at that organisation | D23: THEN the functionality available to me will be that granted by the local organisation, and not necessarily limited to the RBAC roles on my SmartCard | G23: https://evahealthtech.atlassian.net/browse/EJ-1667
A24: Card Identity - Remove Card | B24: GIVEN the user is an authorised Elevate user with a NHS CIC already linked to an Elevate orgranisation they are currently logged in to | C24: WHEN the user removes the card from the card reader | D24: THEN the user is logged out from the Elevate solution
B25: GIVEN the user has a deactivated Elevate account as ORG-A | C25: WHEN the user authenticates themselves using their SmartCard and PIN, and selects ORG-A from the Identity Agent dropdown list | D25: THEN the user shall be refused access to ORG-A within the Elevate application

Sheet ECDS
A2: Product | B2: elevate | D2: #VALUE!
A3: Version
A4: Environment | B4: STAGING
A5: Testing Scenario | B5: ECDS
A8: Domain | B8: GIven | C8: When | D8: Then | E8: Result (pass or fail) | F8: Actual Result (if different) | G8: Jira Ticket
A9: ECDS XML report | B9: Given the patients have encounters created and finalised in elevate | C9: When I trigger the test in lambda for ECDSReportTesting template | D9: Then the XML report is generated in S3 as per ECDS data standards | G9: https://evahealthtech.atlassian.net/browse/EJ-1325
B10: Given the patients have encounters created and finalised in elevate | C10: When I trigger the test in lambda for ECDSReportTesting template with start and enddate maximum of 7 days | D10: Then the XML report is not generated in S3 bucket | G10: https://evahealthtech.atlassian.net/browse/EJ-1325
B11: Given the patients have encounters saved as draft in elevate | C11: When I trigger the test in lambda for ECDSReportTesting template with start and enddate maximum of 7 days | D11: Then the XML report should not contain the encounters saved as draft
A12: Patient Consent | B12: Given the patients consent is Active in elevate | C12: When I trigger the test in lambda for ECDSReportTesting template | D12: Then the XML report is generated in S3 as per ECDS data WITHHELD IDENTITY STRUCTURE standards | G12: https://evahealthtech.atlassian.net/browse/EJ-1324
B13: Given the patients consent is Inactive and PDS synched in elevate | C13: When I trigger the test in lambda for ECDSReportTesting template | D13: Then the XML report is generated in S3 as per ECDS data VERIFIED IDENTITY STRUCTURE | G13: https://evahealthtech.atlassian.net/browse/EJ-1324
B14: Given the patients consent is Inactive and PDS not synched in elevate | C14: When I trigger the test in lambda for ECDSReportTesting template | D14: Then the XML report is generated in S3 as per ECDS data UNVERIFIED IDENTITY STRUCTURE | G14: https://evahealthtech.atlassian.net/browse/EJ-1324
B15: Given the patients consent is Active and PDS not synched in elevate | C15: When I trigger the test in lambda for ECDSReportTesting template | D15: Then the XML report is generated in S3 as per ECDS data WITHHELD IDENTITY STRUCTURE standards
B16: Given the patients(Sensitive patient) have encounters created and finalised in elevate | C16: When I trigger the test in lambda for ECDSReportTesting template | D16: Then the XML report is generated in S3 as per ECDS data WITHHELD IDENTITY STRUCTURE standards | F16: We actually had an UnverifiedIdentity. This is wrong, as the patient IS verified. Good news though is that there is no address included - just a ZZ99 3WZ postcode
A17: About Tab | B17: Given the patients consent is Active in elevate | C17: When I trigger the test in lambda for ECDSReportTesting template | D17: Then the XML report is generated in S3 as per ECDS data WITHHELD IDENTITY STRUCTURE standards | G17: https://evahealthtech.atlassian.net/browse/EJ-1323
B18: Given the patients consent is Inactive and PDS synched in elevate | C18: When I trigger the test in lambda for ECDSReportTesting template | D18: Then the XML report is generated in S3 as per ECDS data VERIFIED IDENTITY STRUCTURE
A19: Table creation | B19: Given the patients have encounters created and finalised in elevate | C19: When I trigger the test in lambda for ECDSReportTesting template | D19: Then the table ecds_reports is generated in the backend with the fields ID, created_at, updated_at - start of time range - end of time range - status - link to created xml (to S3) | G19: https://evahealthtech.atlassian.net/browse/EJ-1330
A20: Notifications | B20: Given the patients have encounters created and finalised in elevate | C20: When there is an error in the ECDS submission process while delivering the ECDS XML file | D20: Then i will be notified via slack | F20: To where? | G20: https://evahealthtech.atlassian.net/browse/EJ-1319
B21: Given the patients have encounters created and finalised in elevate | C21: When there is an error in the ECDS submission process while being acknowledged by SUS+ | D21: Then i will be notified via slack | F21: To where? | G21: https://evahealthtech.atlassian.net/browse/EJ-1319
A22: Audit log | B22: Given the patients have encounters created and finalised in elevate | C22: When I trigger the test in lambda for ECDSReportTesting template | D22: Then i will verify if the audit/Event log is created with the below details: File was created Delivery - fail or success (via MESH) Send attempt - fail or success (receipt acknowledgement) Recipient detail Any errors created | G22: https://evahealthtech.atlassian.net/browse/EJ-1320
A23: ECDS XML extract | B23: Given the feature toggle is ON for ECDS report generation | C23: When I trigger the test in lambda for ECDSReportTesting template | D23: Then the XML report is generated in S3 as per ECDS data standards | F23: no such toggle
B24: Given the feature toggle is OFF for ECDS report generation | C24: When I trigger the test in lambda for ECDSReportTesting template | D24: Then the XML report is not generated in S3 bucket | F24: no such toggle
B25: Given the ODS code of the organisation has been updated in backend/config/aws/.env.tftpl ECDS_SYSTEM_ODS_CODE=<ODS CODE> | C25: When I trigger the test in lambda for ECDSReportTesting template | D25: Then the CDSMessageRecordIdentifier and OrganisationIdentifier_CDSSender elements of the extract will contain the new ODS code

Sheet CPIS
A2: Product | B2: elevate | D2: #VALUE!
A3: Version
A4: Environment | B4: STAGING
A5: Testing Scenario | B5: CPIS
A8: Domain | B8: GIven | C8: When | D8: Then | E8: Result (pass or fail) | F8: Actual Result (if different) | G8: Jira Ticket
A9: Access | B9: Given the logged in user is NOT authorised to access CPIS information | C9: When they load an eligible patient who has CPIS information | D9: Then the CPIS information will not be returned and a message will be displayed stating that may be information available but the user does not have permission to view
B10: Given the logged in user is authorised to access CPIS information | C10: When the user loads an eligible patient and the solution is unable to connect to CPIS | D10: Then a message is displayed warning that CPIS info maybe present but it could not be retrieved
B11: Given the logged in user is authorised to access CPIS information | C11: When they load a patient who has a gender of Male and >=19 years | D11: Then the CPIS service will NOT be queried
B12: Given the logged in user is authorised to access CPIS information | C12: When they load a patient who has a gender of Female and >56 years + 365 days | D12: Then the CPIS service will NOT be queried
B13: Given the logged in user is authorised to access CPIS information | C13: When they load a patient who has a gender of Not Known and >56 years + 365 days | D13: Then the CPIS service will NOT be queried
B14: Given the logged in user is authorised to access CPIS information | C14: When they load a patient who has a gender of Not Specified and >56 years + 365 days | D14: Then the CPIS service will NOT be queried
B15: Given the logged in user is authorised to access CPIS information | C15: When they load a patient who has a gender of Female and >=19 years but <56 years + 365 days | D15: Then the CPIS service will be queried
B16: Given the logged in user is authorised to access CPIS information | C16: When they load a patient who has a gender of Not Known and >=19 years but <56 years + 365 days | D16: Then the CPIS service will be queried
B17: Given the logged in user is authorised to access CPIS information | C17: When they load a patient who has a gender of Not Specified and >=19 years but <56 years + 365 days | D17: Then the CPIS service will be queried
B18: Given the logged in user is authorised to access CPIS information | C18: When they load a patient who has a gender of Female and <= 18 years +365 days | D18: Then the CPIS service will be queried
B19: Given the logged in user is authorised to access CPIS information | C19: When they load a patient who has a gender of Male and <= 18 years +365 days | D19: Then the CPIS service will be queried
B20: Given the logged in user is authorised to access CPIS information | C20: When they load a patient who has a gender of Not Known and <= 18 years +365 days | D20: Then the CPIS service will be queried
B21: Given the logged in user is authorised to access CPIS information | C21: When they load a patient who has a gender of Not Specified and <= 18 years +365 days | D21: Then the CPIS service will be queried
A22: Display of Information | B22: Given the logged in user is authorised to access CPIS information | C22: When they load an eligible patient who has CPIS information | D22: Then an exclamation icon is displayed on the important notes tab
C23: And when the user clicks on the important notes tab | D23: Then the CPIS plan and access information history is displayed for the patient
C24: And when the user refreshes | D24: Then the users access of CPIS has been added to the access history
B25: Given the logged in user is authorised to access CPIS information | C25: When they load a patient who has CPIS information and an important note and view the important note tab | D25: Then the CPIS plan and access information is displayed for the patient along with the important note
A26: Reporting | B26: Given that a Systems Administrator wishes to view a report of CPIS positive traces | C26: When the user loads an eligible patient and the solution is unable to connect to CPIS | D26: Then they shall be able to access the report by navigating to "Reports" from the side bar and selecting "CP-IS" from the ribbon
B27: Given that a non-Systems Administrator wishes to view a report of CPIS positive traces | C27: When the user loads an eligible patient and the solution is unable to connect to CPIS | D27: Then they shall NOT be able to access the report by navigating to "Reports" from the side bar and selecting "CP-IS" from the ribbon
B28: Given that a patient that falls WITHIN the qualifying CP-IS age range is retrieved by a user WITH the prerequisite rights to access CPIS information AND the patient HAS a current CPIS care plan | C28: When a Systems Administrator runs the PID variant of the CP-IS report | D28: The Systems Administrator will be able ascertain the following details: - NHS Number - Patient Name - DoB - Date/time of positive CP-IS trace - User that accessed CP-IS
B29: Given that a patient that falls WITHIN the qualifying CP-IS age range is retrieved by a user WITH the prerequisite rights to access CPIS information AND the the patient HAS a current CPIS care plan | C29: When a Systems Administrator runs the NON-PID variant of the CP-IS report | D29: The Systems Administrator will be able ascertain the following details: - Date/time of positive CP-IS trace - User that accessed CP-IS
B30: Given that a patient that falls WITHIN the qualifying CP-IS age range is retrived by a user WITHOUT the prerequisite rights to access CPIS information | C30: When a Systems Administrator runs the CP-IS report | D30: Then no record of the event of loading the patient shall be shown
B31: Given that a patient that falls OUTSIDE the qualifying CP-IS age range is retrieved by a user WITH the prerequisite rights to access CPIS information | C31: When a Systems Administrator runs the CP-IS report | D31: Then no record of the event of loading the patient shall be shown
B32: Given that a patient that falls WITHIN the qualifying CP-IS age range is retrieved by a user WITH the prerequisite rights to access CPIS information ONE MORE THAN ONE OCCASION WITHIN THE REPORTING PERIOD | C32: When a Systems Administrator runs the CP-IS report | D32: Then each instance of the patient retrieval is shown, with details showing - NHS Number - Patient Name - DoB - Date/time of positive CP-IS trace - User that accessed CP-IS
B33: Given that a patient that falls WITHIN the qualifying CP-IS age range is retrieved by a user WITH the prerequisite rights to access CPIS information BUT the patient DOES NOT have a current CPIS care plan | C33: When a Systems Administrator runs the PID variant of the CP-IS report | D33: Then no record of the event of loading the patient shall be shown
B34: Given that a Systems Administrator clicks on the button "Today" | C34: When a Systems Administrator runs the CP-IS report | D34: Only CP-IS positive trace events will be shown for the period of TODAY
B35: Given that a Systems Administrator clicks on the button "This Month" | C35: When a Systems Administrator runs the CP-IS report | D35: Only CP-IS positive trace events will be shown for the period of THIS MONTH
B36: Given that a Systems Administrator enters a specific date/time range | C36: When a Systems Administrator runs the CP-IS report | D36: Only CP-IS positive trace events will be shown for the period of that time range

Sheet ITK3
A2: Product | B2: elevate | D2: #VALUE!
A3: Version
A4: Environment | B4: STAGING
A5: Testing Scenario | B5: ITK3
A8: Domain | B8: GIven | C8: When | D8: Then | E8: Result (pass or fail) | F8: Actual Result (if different) | G8: Jira Ticket

Sheet GPC-SD
A2: Product | B2: elevate | D2: #VALUE!
A3: Version
A4: Environment | B4: STAGING
A5: Testing Scenario | B5: GP Connect Send Document (GPC-SD)
B8: (*) To create an Encounter record...
B9: 1. Log into "Smalpox Clinic" and load a chosen patient
B10: 2. Enter into "Timeline" and select "Add new Encounter"
B11: 3. Select a template - such as "Consultation Notes"
B12: 4. Complete the template and click "Finalise"
B14: NOTE - For patient context, use patient 9449304831 Jools BAALOUD for ALL tests | D14: Testing arrangements for GP Connect Send Document against the NHSE GPC-SD test harness is unusual.
B15: NOTE - For user context use u/name "roger_501@ummanu.health", password "protectMe!" | D15: For each testing scenario, change the forename of the HCP to the code specified in the test to mock the desired response
A17: Domain | B17: GIven | C17: When | D17: Then | E17: Result (pass or fail) | F17: Actual Result (if different) | G17: Jira Ticket
A18: GENERAL UI CHECKS | B18: GIVEN I wish to create a GPC-SD for a patient that has been successfully PDS traced | C18: WHEN I create an Encounter record (*) | D18: THEN the "Send Document for GP Connect" tickbox should be available, checked and no warnings shall be shown | H18: Use Otto McEVOY (967 496 0015)
B19: GIVEN I wish to create a GPC-SD for a patient that has NOT been successfully PDS traced | C19: WHEN I create an Encounter record (*) | D19: THEN I shall be warned that it is not possible to send the summary electronically for this patient as they have no ODS code AND the "Send Document for GP Connect" tickbox should be unavailable for selection | H19: Use a locally-registered patient
B20: GIVEN I wish to create a GPC-SD for a patient that is locally DECEASED | C20: WHEN I create an Encounter record (*) | D20: THEN the "Send Document for GP Connect" tickbox should be available, checked and no warnings shall be shown
B21: GIVEN I wish to create a GPC-SD for a patient that is DECEASED on the recipient system (their registered GP system) | C21: WHEN I have created an Encounter record (*) using a HCP account with the forename "30004" | D21: THEN the GPC-SD should adopt the state of "ERROR" with the tooltip text "Patient known here and recently deceased"
B22: GIVEN I wish to create a GPC-SD for a patient that DOES NOT have a registered practice ODS Code | C22: WHEN I create an Encounter record (*) | D22: THEN the "Send Document for GP Connect" tickbox should be available, checked and no warnings shall be shown
B23: GIVEN I wish to create a GPC-SD for a locally-registered patient | C23: WHEN I create an Encounter record (*) | D23: THEN I shall be warned that it is not possible to send the summary electronically for this patient as they have not been synchronised with PDS
B24: GIVEN that I've created an Encounter using a template that supports attachments AND I've attached one or more files | C24: WHEN I click on Finalise | D24: THEN I should be warned that the Encounter attachments will not be sent with the electronic message, and I should finalise the doucment WITHOUT sending it
A25: NO KNOWN ODS CODE FOR PATIENT | B25: GIVEN I wish to create a GPC-SD for a patient NOT KNOWN at the specified practice ODS code | C25: WHEN I create an Encounter record (*) | D25: THEN I shall be warned that it is not possible to send a the summary electronically for this patient as they have no ODS code AND the "Send Document for GP Connect" tickbox should be unavailable for selection
A26: TEST HARNESS RESPONSES - BUSINESS LEVEL RESPONSE | B26: GIVEN I wish to create a GPC-SD for a patient that is registered on the recipient system | C26: WHEN I have created an Encounter record (*) using a HCP account with the forename "30001" | D26: THEN the GPC-SD should adopt the state of "SENT" with the tooltip text "Patient known here. (e.g. Patient is registered here)"
B27: GIVEN I wish to create a GPC-SD for a patient that is NOT registered on the recipient system | C27: WHEN I have created an Encounter record (*) using a HCP account with the forename "30002" | D27: THEN the GPC-SD should adopt the state of "ERROR" with the tooltip text "Patient not known here. (aka ‘patient record not present in system’)"
B28: GIVEN I wish to create a GPC-SD for a patient that is NOT registered on the recipient system | C28: WHEN I have created an Encounter record (*) using a HCP account with the forename "30016" | D28: THEN the GPC-SD should adopt the state of "SENT" with the tooltip text "Referral accepted"
B29: GIVEN I wish to create a GPC-SD for a patient that is registered on the recipient system | C29: WHEN I have created an Encounter record (*) using a HCP account with the forename "30017" | D29: THEN the GPC-SD should adopt the state of "ERROR" with the tooltip text "Referral rejected"
